Workbook

Sheet INVOICE
A1: COMMERCIAL INVOICE
A2: 1) Shipper / Exporter | F2: 8) No. & Date of Invoice
B4: KNK CO.,LTD | G4: KNK-260402-1 | H4: DATE: | I4: 46114
B5: 2, Gisan-ro 87 beon-gil, Hwaseong-si, Gyeonggi-do, Korea.
B6: TEL : +82-70-4045-0407 | D6: FAX: +82-31-267-0407
F7: 9) No. & Date of L/C
B8: ATTN : Ji-Yeon, An (+82-10-2739-2660)
A10: 2) For Account & Risk of Messrs | F10: T/T
B12: KNK VINA Co., Ltd.
B13: LOT CN5B-2,QUE VO III INDUSTRIAL PARK, | F13: 10) Issuing Bank
B14: QUE VO WARD, BAC NINH PROVINCE, VIETNAM.
B17: ATTN : NGUYEN DINH TAM (+84-98-204-9966)
A19: 3) Notify Party | F19: 11) Remarks
B21: SAME AS ABOVE | G21: INCOTERMS : C.I.P
A24: 4) Port of Loading | D24: 5) Final Destination
A25: Incheon, Korea | D25: Hanoi, Vietnam
A28: 6) Carrier | D28: 7) Sailing On or About | M28: 베트남 세관 HS CODE
D29: 46116
A31: 12) Marks and Number of PKGS | D31: 13) Description of Goods | F31: 14) Q'ty /Unit | H31: 15) Unit Price | I31: 16) Amount | K31: ORIGIN | L31: Loại hình | M31: CATEGORY | N31: HS CODE
B34: 001M2603 | D34: SRS1-C1202-2 | F34: 14 | H34: 9.83 | I34: =F34*H34 -> 137.62 | J34: Fold 부착기(CTC) 2대 | K34: KOREA | M34: SSR | N34: 85364199 | O34: Rơ le bán dẫn, mã hàng: SRS1-C1202-2, điện áp: 24V, dòng điện: 2A, hsx: Autonics, hàng mới 100%
B35: 001M2603 | D35: PS-DS1001-25P | F35: 4 | H35: 0.23 | I35: =F35*H35 -> 0.92 | J35: Fold 부착기(CTC) 2대 | K35: CHINA | M35: D-SUB HOOD | N35: 39269099 | O35: Vỏ bảo vệ đầu nối, mã hàng: PS-DS1001-25P, chất liệu chủ yếu: nhựa, hsx: Connfly, hàng mới 100%
B36: 001M2603 | D36: DCP32DN 3A | F36: 14 | H36: 13.81 | I36: =F36*H36 -> 193.34 | J36: Fold 부착기(CTC) 2대 | K36: KOREA | M36: MCB | N36: 85362011 | O36: Cầu dao điện, mã hàng: DCP32DN 3A, loại hộp đúc, dòng điện 3A, hsx: Daco, hàng mới 100%
B37: 001M2603 | D37: DCP32DN 15A | F37: 2 | H37: 13.81 | I37: =F37*H37 -> 27.62 | J37: Fold 부착기(CTC) 2대 | K37: KOREA | M37: MCB | N37: 85362011 | O37: Cầu dao điện, mã hàng: DCP32DN 15A, loại hộp đúc, dòng điện: 3A, hsx: Daco, hàng mới 100%
B38: 001M2603 | D38: AFB1224M-F00/AFB1224M | F38: 2 | H38: 9.36 | I38: =F38*H38 -> 18.72 | J38: Fold 부착기(CTC) 2대 | K38: TAIWAN | M38: 냉각팬 | N38: 84145949 | O38: COOLING FAN-GC#&Quạt tản nhiệt dùng cho tủ điện, mã hàng: AFB1224M, không có lưới, điện áp 24V, kích thước: 120x120x25.4mm, hàng mới 100%
B39: 001M2603 | D39: AFB1224SHE-R00 | F39: 2 | H39: 12.64 | I39: =F39*H39 -> 25.28 | J39: Fold 부착기(CTC) 2대 | K39: TAIWAN | M39: 냉각팬 | N39: 84145949 | O39: Quạt tản nhiệt dùng cho tủ điện, mã hàng: AFB1224SHE-R00, không có lưới, điện áp 24V, 0.75A, kích thước: 120x120x38mm, hàng mới 100%
B40: 001M2603 | D40: D-SUB 25 Pin / Female | F40: 4 | H40: 0.27 | I40: =F40*H40 -> 1.08 | J40: Fold 부착기(CTC) 2대 | K40: KOREA | M40: D-SUB 25 Pin / Female | N40: 85369012 | O40: Đầu nối, mã hàng:D-SUB 25 Pin / Female, loại 25 chân, dùng cho dòng điện dưới 16A, hàng mới 100%
B41: 001M2603 | D41: T-DFF120 | F41: 4 | H41: 0.53 | I41: =F41*H41 -> 2.12 | J41: Fold 부착기(CTC) 2대 | K41: KOREA | M41: 커버 | N41: 84213990 | O41: Quạt lọc khí, mã hàng: T-DFF120, hsx: T-TECHNOLOGY, hàng mới 100%
B42: 001M2603 | D42: 120*120 | F42: 4 | H42: 0.31 | I42: =F42*H42 -> 1.24 | J42: Fold 부착기(CTC) 2대 | K42: KOREA | M42: 스틸망 | N42: 73269099 | O42: Vỏ che ngoài của quạt tản nhiệt, mã hàng: MG-120, kích thước: 120*120(mm), chất liệu: thép, hsx: WOONYOUNG, hàng mới 100%
B43: 001M2603 | D43: BK10S-T2-2P | F43: 2 | H43: 31.06 | I43: =F43*H43 -> 62.12 | J43: Fold 부착기(CTC) 2대 | K43: KOREA | M43: SPD_KS | N43: 85363010 | O43: Thiết bị chống sét, mã hàng: BK10S-T2-2P, 2 cực, điện áp: 230/440V AC, hsx: LS, hàng mới 100%
B44: 001M2603 | D44: SD10-T2-2P | F44: 2 | H44: 42.76 | I44: =F44*H44 -> 85.52 | J44: Fold 부착기(CTC) 2대 | K44: KOREA | M44: SPD CP_KS | N44: 85363010 | O44: Thiết bị chống sét, mã hàng: SD10-T2-2P(20KA), 2 cực, điện áp: 230/440V AC, hsx: LS, hàng mới 100%
B45: 001M2603 | D45: G7SA-2A2B | F45: 8 | H45: 8.19 | I45: =F45*H45 -> 65.52 | J45: Fold 부착기(CTC) 2대 | K45: JAPAN | M45: Safety Relay Coil | N45: 85364199 | O45: Rơ le, mã hàng: G7SA-2A2B, điện áp: 24v, hsx: OMRON, hàng mới 100%
... B166: 001M2603 | D166: SS6000ZZS | F166: 48 | H166: 0.66 | I166: =F166*H166 -> 31.68 | J166: Fold 부착기(CTC) 2대 | K166: KOREA | M166: BEARING | N166: 84821000 | O166: Vòng bi, mã hàng: SS6000ZZS chất liệu: thép không gỉ, đường kính: 26mm, hsx: Misumi, hàng mới 100%
B167: 001M2603 | D167: MCH15N-2-680L R/D / LMG15H 2UU+680L ES10 R/D / E-HLGH15-680-B2-ES10-R | F167: 8 | H167: 37.45 | I167: =F167*H167 -> 299.6 | J167: Fold 부착기(CTC) 2대 | K167: KOREA | M167: LM GUIDE | N167: 73269099 | O167: Thanh trượt dẫn hướng
B168: 001M2603 | D168: 6001ZZS | F168: 16 | H168: 0.39 | I168: =F168*H168 -> 6.24 | J168: Fold 부착기(CTC) 2대 | K168: KOREA | M168: BEARING | N168: 84821000 | O168: BEARING#&Vòng bi, mã hàng: 6001ZZS, chất liệu: thép không gỉ, đường kính: 24 mm, hsx: Misumi, hàng mới 100%
B169: 001M2603 | D169: MCH15N-1-470L R/D / LMG15HUU+470L ES25 R/D / E-HLGH15-470-ES25-R | F169: 2 | H169: 22.63 | I169: =F169*H169 -> 45.26 | J169: Fold 부착기(CTC) 2대 | K169: KOREA | M169: LM GUIDE | N169: 73269099 | O169: Thanh trượt dẫn hướng
B170: 001M2603 | D170: MCH15N-2-1070L R/D / LMG15H 2UU+1070L ES25 R/D / E-HLGH15-1070-B2-ES25-R | F170: 2 | H170: 48.38 | I170: =F170*H170 -> 96.76 | J170: Fold 부착기(CTC) 2대 | K170: KOREA | M170: LM GUIDE | N170: 73269099 | O170: Thanh trượt dẫn hướng
B171: 001M2603 | D171: MCM12W-2-162L R/D / LMNW12T 2UU+162L ES21 R/D / %ELLG-E-SMLGW7H-162-B2-ES21-R | F171: 2 | H171: 27.93 | I171: =F171*H171 -> 55.86 | J171: Fold 부착기(CTC) 2대 | K171: KOREA | M171: LM GUIDE | N171: 73269099 | O171: Thanh trượt dẫn hướng
B172: 001M2603 | D172: SS6800ZZ | F172: 8 | H172: 0.62 | I172: =F172*H172 -> 4.96 | J172: Fold 부착기(CTC) 2대 | K172: KOREA | M172: BEARING | N172: 84821000 | O172: Vòng bi
B173: 001M2603 | D173: S6901ZZS | F173: 16 | H173: 0.59 | I173: =F173*H173 -> 9.44 | J173: Fold 부착기(CTC) 2대 | K173: KOREA | M173: BEARING | N173: 84821000 | O173: Vòng bi, mã hàng: S6901ZZS, chất liệu: thép không gỉ, đường kính: 24 mm, hsx: Misumi, hàng mới 100%
B174: 001M2603 | D174: MCM9M-1-50L R/D / LMN9T+50L ES5 R/D / C-MLG9-50-ES5-R | F174: 4 | H174: 10.14 | I174: =F174*H174 -> 40.56 | J174: Fold 부착기(CTC) 2대 | K174: KOREA | M174: LM GUIDE | N174: 73269099 | O174: Thanh trượt dẫn hướng
...

Sheet PACKING LIST
A1: PACKING LIST
A2: 1) Shipper / Exporter | F2: 8) No. & Date of Invoice
B4: KNK CO.,LTD | G4: =++INVOICE!G4 -> KNK-260402-1 | I4: DATE : | J4: =++INVOICE!I4 -> 46114
B5: 2, Gisan-ro 87 beon-gil, Hwaseong-si, Gyeonggi-do, Korea.
B6: TEL : +82-70-4045-0407 | D6: FAX: +82-31-267-0407
F7: 9) No. & Date of L/C
B8: ATTN : Ji-Yeon, An (+82-10-2739-2660)
A10: 2) For Account & Risk of Messrs | F10: T/T
B12: KNK VINA Co., Ltd.
B13: LOT CN5B-2,QUE VO III INDUSTRIAL PARK, | F13: 10) Issuing Bank
B14: QUE VO WARD, BAC NINH PROVINCE, VIETNAM.
B17: ATTN : NGUYEN DINH TAM (+84-98-204-9966)
A19: 3) Notify Party | F19: 11) Remarks
B21: SAME AS ABOVE | G21: INCOTERMS : C.I.P
A28: 4) Port of Loading | D28: 5) Final Destination
A29: =++INVOICE!A25 -> Incheon, Korea | D29: =++INVOICE!D25 -> Hanoi, Vietnam
A32: 6) Carrier | D32: 7) Sailing On or About
D33: =++INVOICE!D29 -> 46116
A35: 12) Marks and Number of PKGS | D35: 13) Description of Goods | F35: 14) Q'ty /Unit | H35: Net - | I35: Gross- | J35: Measurement | M35: NO. | N35: SIZE | O35: G/W
H36: Weight | I36: Weight
M37: 1 | N37: 1,100*1,100*1,680(H) | O37: 435
B38: 001M2603 | D38: SRS1-C1202-2 | F38: 14 | H38: =420+250 -> 670 | I38: =435+260 -> 695 | J38: 2 | M38: 2 | N38: 1,450*1,100*1,350(H) | O38: 260
B39: 001M2603 | D39: PS-DS1001-25P | F39: 4 | O39: =++SUM(O37:O38) -> 695
B40: 001M2603 | D40: DCP32DN 3A | F40: 14
B41: 001M2603 | D41: DCP32DN 15A | F41: 2
B42: 001M2603 | D42: AFB1224M-F00/AFB1224M | F42: 2
B43: 001M2603 | D43: AFB1224SHE-R00 | F43: 2
B44: 001M2603 | D44: D-SUB 25 Pin / Female | F44: 4
B45: 001M2603 | D45: T-DFF120 | F45: 4
B46: 001M2603 | D46: 120*120 | F46: 4
B47: 001M2603 | D47: BK10S-T2-2P | F47: 2
B48: 001M2603 | D48: SD10-T2-2P | F48: 2
B49: 001M2603 | D49: G7SA-2A2B | F49: 8
B50: 001M2603 | D50: P7SA-10F-ND | F50: 8
B51: 001M2603 | D51: G9SP-N10S | F51: 2
... B189: 001M2603 | D189: MMC_BDP008PCB | F189: 2
B190: 002M2603 | C190: 1 | D190: BS5-Y2M | F190: 2
B191: 002M2603 | C191: 2 | D191: CT-02 5M | F191: 2
B192: 002M2603 | C192: 3 | D192: D40A_1C2 | F192: 4
B193: 002M2603 | C193: 4 | D193: SRS1-C1202-2 | F193: 7
...
